Workbook

Sheet README
A1: ASCENDANCE — Master Data Tables v3
A3: Legend | B3: Blue text = hardcoded design inputs (tunable). Black = formulas. Yellow fill = cells you edit (Level_Calculator!D1).
A4: Grades_Realms | B4: The 42-grade spine (14 cultivation realms × 3 stages) shared by buildings, research disciplines, and player cultivation. Levels 0–1337; a grade every 32 levels.
A5: Building_Levels | B5: Parametric multipliers for every building at levels 0–1337 (cost/time/output curves).
A6: Buildings_Master | B6: All 483 buildings (69 per era × 7 eras) with categories and base costs in era-currency equivalents.
A7: Level_Calculator | B7: Type any building name into the yellow cell; the sheet computes its full 0–1337 cost/time/output table.
A8: Archetypes / Unit_Grades / Unit_Paths | B8: Base unit stats and the multipliers that generate the full roster.
A9: Units_Master | B9: 2,268 units (18 archetypes × 3 identity paths × 6 grades × 7 eras), stats computed by formula from the three parameter sheets. "100s of troop types per era" arises combinatorially from research grade + identity path progression.
A10: Counter_Matrix | B10: Role-vs-role damage multipliers (34 roles). Applied on top of unit stats in combat resolution.
A11: Research_Disciplines | B11: 21 disciplines (3 branches × 7 eras), each 0–1337 levels / 42 grades, with prerequisites.
A12: Equipment_Catalog | B12: 135 equipment lines (3 slots × 9 tiers × 5 qualities) with formula-driven bonuses.
A13: Celestial_Sites | B13: 41 site types: barren villages and ruins through planets, moons, asteroids, and intergalactic void sites.
A14: Cultivation | B14: The Sovereign's Path system summary (full design in GDD v3 addendum).
... A42: Empire_Weight_Multiplier | B42: Veterancy XP REQUIREMENT multiplier by empire size: the soft-knee curve to a 9,918,521x cap, why the requirement side beats the earn side, scope, the Champion economy, and countermeasures.

Sheet Grades_Realms
A1: Grade # | B1: Realm · Stage | C1: Min Level | D1: Max Level | E1: Breakthrough Qi Cost | F1: Tribulation (cultivation) | G1: Building Breakthrough Project | H1: Research Grade Prerequisite
A2: 1 | B2: Mortal Vessel · Initial | C2: =(A2-1)*32 -> 0 | D2: =MIN(1337, A2*32-1) -> 31 | E2: =ROUND(100*A2^3.2*1.15^A2,0) -> 115 | F2: None — mortal effort only | G2: Grade-Up Project G1: consumes era resources; 32×level-time; attackable while building | H2: None
A3: 2 | B3: Mortal Vessel · Advanced | C3: =(A3-1)*32 -> 32 | D3: =MIN(1337, A3*32-1) -> 63 | E3: =ROUND(100*A3^3.2*1.15^A3,0) -> 1215 | F3: None — mortal effort only | G3: Grade-Up Project G2: consumes era resources; 32×level-time; attackable while building | H3: All 3 same-era disciplines at Grade 1; cultivation realm ≥ G1
A4: 3 | B4: Mortal Vessel · Perfected | C4: =(A4-1)*32 -> 64 | D4: =MIN(1337, A4*32-1) -> 95 | E4: =ROUND(100*A4^3.2*1.15^A4,0) -> 5115 | F4: None — mortal effort only | G4: Grade-Up Project G3: consumes era resources; 32×level-time; attackable while building | H4: All 3 same-era disciplines at Grade 2; cultivation realm ≥ G2
A5: 4 | B5: Awakened Meridian · Initial | C5: =(A5-1)*32 -> 96 | D5: =MIN(1337, A5*32-1) -> 127 | E5: =ROUND(100*A5^3.2*1.15^A5,0) -> 14770 | F5: Minor Awakened Meridian trial | G5: Grade-Up Project G4: consumes era resources; 32×level-time; attackable while building | H5: All 3 same-era disciplines at Grade 3; cultivation realm ≥ G3
A6: 5 | B6: Awakened Meridian · Advanced | C6: =(A6-1)*32 -> 128 | D6: =MIN(1337, A6*32-1) -> 159 | E6: =ROUND(100*A6^3.2*1.15^A6,0) -> 34689 | F6: Minor Awakened Meridian trial | G6: Grade-Up Project G5: consumes era resources; 32×level-time; attackable while building | H6: All 3 same-era disciplines at Grade 4; cultivation realm ≥ G4
A7: 6 | B7: Awakened Meridian · Perfected | C7: =(A7-1)*32 -> 160 | D7: =MIN(1337, A7*32-1) -> 191 | E7: =ROUND(100*A7^3.2*1.15^A7,0) -> 71494 | F7: Trial of Hunger: survive a famine tick without starvation losses | G7: Grade-Up Project G6: consumes era resources; 32×level-time; attackable while building | H7: All 3 same-era disciplines at Grade 5; cultivation realm ≥ G5
A8: 7 | B8: Tempered Body · Initial | C8: =(A8-1)*32 -> 192 | D8: =MIN(1337, A8*32-1) -> 223 | E8: =ROUND(100*A8^3.2*1.15^A8,0) -> 134648 | F8: Minor Tempered Body trial | G8: Grade-Up Project G7: consumes era resources; 32×level-time; attackable while building | H8: All 3 same-era disciplines at Grade 6; cultivation realm ≥ G6
A9: 8 | B9: Tempered Body · Advanced | C9: =(A9-1)*32 -> 224 | D9: =MIN(1337, A9*32-1) -> 255 | E9: =ROUND(100*A9^3.2*1.15^A9,0) -> 237395 | F9: Minor Tempered Body trial | G9: Grade-Up Project G8: consumes era resources; 32×level-time; attackable while building | H9: All 3 same-era disciplines at Grade 7; cultivation realm ≥ G7
A10: 9 | B10: Tempered Body · Perfected | C10: =(A10-1)*32 -> 256 | D10: =MIN(1337, A10*32-1) -> 287 | E10: =ROUND(100*A10^3.2*1.15^A10,0) -> 397976 | F10: Beast Tide: defend home settlement vs. NPC wave | G10: Grade-Up Project G9: consumes era resources; 32×level-time; attackable while building | H10: All 3 same-era disciplines at Grade 8; cultivation realm ≥ G8
A11: 10 | B11: Foundation · Initial | C11: =(A11-1)*32 -> 288 | D11: =MIN(1337, A11*32-1) -> 319 | E11: =ROUND(100*A11^3.2*1.15^A11,0) -> 641178 | F11: Minor Foundation trial | G11: Grade-Up Project G10: consumes era resources; 32×level-time; attackable while building | H11: All 3 same-era disciplines at Grade 9; cultivation realm ≥ G9
A12: 11 | B12: Foundation · Advanced | C12: =(A12-1)*32 -> 320 | D12: =MIN(1337, A12*32-1) -> 351 | E12: =ROUND(100*A12^3.2*1.15^A12,0) -> 1000306 | F12: Minor Foundation trial | G12: Grade-Up Project G11: consumes era resources; 32×level-time; attackable while building | H12: All 3 same-era disciplines at Grade 10; cultivation realm ≥ G10
A13: 12 | B13: Foundation · Perfected | C13: =(A13-1)*32 -> 352 | D13: =MIN(1337, A13*32-1) -> 383 | E13: =ROUND(100*A13^3.2*1.15^A13,0) -> 1519687 | F13: Heart Demon: agent-op puzzle event; failure stuns cultivation 48h | G13: Grade-Up Project G12: consumes era resources; 32×level-time; attackable while building | H13: All 3 same-era disciplines at Grade 11; cultivation realm ≥ G11
... A43: 42 | B43: Transcendent Dao · Perfected | C43: =(A43-1)*32 -> 1312 | D43: =MIN(1337, A43*32-1) -> 1337 | E43: =ROUND(100*A43^3.2*1.15^A43,0) -> 5542516876 | F43: The Question: universe-unique riddle-quest chain, one per epoch may pass | G43: Grade-Up Project G42: consumes era resources; 32×level-time; attackable while building | H43: All 3 same-era disciplines at Grade 41; cultivation realm ≥ G41
B45: Assumption: 42 grades × 32 levels = 1344 cap, truncated to level 1337 (Grade 42 spans 1312–1337). Qi cost curve is a design input (blue-style constant), tunable server-side.

Sheet Building_Levels
A1: Level | B1: Grade # | C1: Realm · Stage | D1: Cost Multiplier | E1: Build/Research Time (hours) | F1: Output Multiplier | G1: Cumulative Hours 0→L | I1: Time constant K (h)
A2: 0 | B2: =MIN(42, FLOOR(A2/32,1)+1) -> 1 | C2: =INDEX(Grades_Realms!$B$2:$B$43, B2) -> Mortal Vessel · Initial | D2: =(A2+1)^2.4 * 1.004^A2 -> 1 | E2: =$I$2*(A2+1)^1.9*1.003^A2 -> 0.00043197749 | F2: =(A2+1)^1.12 -> 1 | G2: =E2 -> 0.00043197749 | I2: 0.00043197749
A3: 1 | B3: =MIN(42, FLOOR(A3/32,1)+1) -> 1 | C3: =INDEX(Grades_Realms!$B$2:$B$43, B3) -> Mortal Vessel · Initial | D3: =(A3+1)^2.4 * 1.004^A3 -> 5.2991438 | E3: =$I$2*(A3+1)^1.9*1.003^A3 -> 0.0016170336 | F3: =(A3+1)^1.12 -> 2.1734697 | G3: =G2+E3 -> 0.0020490111 | I3: Calibrated so SUM of time col = 500 years (1 yr = 8766 h). Design input.
A4: 2 | B4: =MIN(42, FLOOR(A4/32,1)+1) -> 1 | C4: =INDEX(Grades_Realms!$B$2:$B$43, B4) -> Mortal Vessel · Initial | D4: =(A4+1)^2.4 * 1.004^A4 -> 14.078567 | E4: =$I$2*(A4+1)^1.9*1.003^A4 -> 0.0035042361 | F4: =(A4+1)^1.12 -> 3.4227549 | G4: =G3+E4 -> 0.0055532472
A5: 3 | B5: =MIN(42, FLOOR(A5/32,1)+1) -> 1 | C5: =INDEX(Grades_Realms!$B$2:$B$43, B5) -> Mortal Vessel · Initial | D5: =(A5+1)^2.4 * 1.004^A5 -> 28.193248 | E5: =$I$2*(A5+1)^1.9*1.003^A5 -> 0.0060712469 | F5: =(A5+1)^1.12 -> 4.7239706 | G5: =G4+E5 -> 0.011624494 | I5: Total climb (hours) | J5: Total climb (years)
A6: 4 | B6: =MIN(42, FLOOR(A6/32,1)+1) -> 1 | C6: =INDEX(Grades_Realms!$B$2:$B$43, B6) -> Mortal Vessel · Initial | D6: =(A6+1)^2.4 * 1.004^A6 -> 48.357391 | E6: =$I$2*(A6+1)^1.9*1.003^A6 -> 0.0093048174 | F6: =(A6+1)^1.12 -> 6.0652179 | G6: =G5+E6 -> 0.020929312 | I6: =SUM(E2:E1339) -> 4383000 | J6: =SUM(E2:E1339)/8766 -> 500
A7: 5 | B7: =MIN(42, FLOOR(A7/32,1)+1) -> 1 | C7: =INDEX(Grades_Realms!$B$2:$B$43, B7) -> Mortal Vessel · Initial | D7: =(A7+1)^2.4 * 1.004^A7 -> 75.202376 | E7: =$I$2*(A7+1)^1.9*1.003^A7 -> 0.01319633 | F7: =(A7+1)^1.12 -> 7.4392542 | G7: =G6+E7 -> 0.034125641
A8: 6 | B8: =MIN(42, FLOOR(A8/32,1)+1) -> 1 | C8: =INDEX(Grades_Realms!$B$2:$B$43, B8) -> Mortal Vessel · Initial | D8: =(A8+1)^2.4 * 1.004^A8 -> 109.30438 | E8: =$I$2*(A8+1)^1.9*1.003^A8 -> 0.017739974 | F8: =(A8+1)^1.12 -> 8.8411713 | G8: =G7+E8 -> 0.051865616
A9: 7 | B9: =MIN(42, FLOOR(A9/32,1)+1) -> 1 | C9: =INDEX(Grades_Realms!$B$2:$B$43, B9) -> Mortal Vessel · Initial | D9: =(A9+1)^2.4 * 1.004^A9 -> 151.20006 | E9: =$I$2*(A9+1)^1.9*1.003^A9 -> 0.022931825 | F9: =(A9+1)^1.12 -> 10.267407 | G9: =G8+E9 -> 0.074797441
A10: 8 | B10: =MIN(42, FLOOR(A10/32,1)+1) -> 1 | C10: =INDEX(Grades_Realms!$B$2:$B$43, B10) -> Mortal Vessel · Initial | D10: =(A10+1)^2.4 * 1.004^A10 -> 201.39641 | E10: =$I$2*(A10+1)^1.9*1.003^A10 -> 0.028769303 | F10: =(A10+1)^1.12 -> 11.715251 | G10: =G9+E10 -> 0.10356674
A11: 9 | B11: =MIN(42, FLOOR(A11/32,1)+1) -> 1 | C11: =INDEX(Grades_Realms!$B$2:$B$43, B11) -> Mortal Vessel · Initial | D11: =(A11+1)^2.4 * 1.004^A11 -> 260.37748 | E11: =$I$2*(A11+1)^1.9*1.003^A11 -> 0.035250843 | F11: =(A11+1)^1.12 -> 13.182567 | G11: =G10+E11 -> 0.13881759
A12: 10 | B12: =MIN(42, FLOOR(A12/32,1)+1) -> 1 | C12: =INDEX(Grades_Realms!$B$2:$B$43, B12) -> Mortal Vessel · Initial | D12: =(A12+1)^2.4 * 1.004^A12 -> 328.60909 | E12: =$I$2*(A12+1)^1.9*1.003^A12 -> 0.042375667 | F12: =(A12+1)^1.12 -> 14.667625 | G12: =G11+E12 -> 0.18119325
A13: 11 | B13: =MIN(42, FLOOR(A13/32,1)+1) -> 1 | C13: =INDEX(Grades_Realms!$B$2:$B$43, B13) -> Mortal Vessel · Initial | D13: =(A13+1)^2.4 * 1.004^A13 -> 406.54239 | E13: =$I$2*(A13+1)^1.9*1.003^A13 -> 0.050143627 | F13: =(A13+1)^1.12 -> 16.168994 | G13: =G12+E13 -> 0.23133688
A14: 12 | B14: =MIN(42, FLOOR(A14/32,1)+1) -> 1 | C14: =INDEX(Grades_Realms!$B$2:$B$43, B14) -> Mortal Vessel · Initial | D14: =(A14+1)^2.4 * 1.004^A14 -> 494.6165 | E14: =$I$2*(A14+1)^1.9*1.003^A14 -> 0.058555094 | F14: =(A14+1)^1.12 -> 17.685468 | G14: =G13+E14 -> 0.28989197
A15: 13 | B15: =MIN(42, FLOOR(A15/32,1)+1) -> 1 | C15: =INDEX(Grades_Realms!$B$2:$B$43, B15) -> Mortal Vessel · Initial | D15: =(A15+1)^2.4 * 1.004^A15 -> 593.26066 | E15: =$I$2*(A15+1)^1.9*1.003^A15 -> 0.067610868 | F15: =(A15+1)^1.12 -> 19.216018 | G15: =G14+E15 -> 0.35750284
A16: 14 | B16: =MIN(42, FLOOR(A16/32,1)+1) -> 1 | C16: =INDEX(Grades_Realms!$B$2:$B$43, B16) -> Mortal Vessel · Initial | D16: =(A16+1)^2.4 * 1.004^A16 -> 702.89589 | E16: =$I$2*(A16+1)^1.9*1.003^A16 -> 0.077312118 | F16: =(A16+1)^1.12 -> 20.759754 | G16: =G15+E16 -> 0.43481496
A17: 15 | B17: =MIN(42, FLOOR(A17/32,1)+1) -> 1 | C17: =INDEX(Grades_Realms!$B$2:$B$43, B17) -> Mortal Vessel · Initial | D17: =(A17+1)^2.4 * 1.004^A17 -> 823.93633 | E17: =$I$2*(A17+1)^1.9*1.003^A17 -> 0.087660325 | F17: =(A17+1)^1.12 -> 22.315899 | G17: =G16+E17 -> 0.52247529
A18: 16 | B18: =MIN(42, FLOOR(A18/32,1)+1) -> 1 | C18: =INDEX(Grades_Realms!$B$2:$B$43, B18) -> Mortal Vessel · Initial | D18: =(A18+1)^2.4 * 1.004^A18 -> 956.79042 | E18: =$I$2*(A18+1)^1.9*1.003^A18 -> 0.098657247 | F18: =(A18+1)^1.12 -> 23.883765 | G18: =G17+E18 -> 0.62113253
... A1339: 1337 | B1339: =MIN(42, FLOOR(A1339/32,1)+1) -> 42 | C1339: =INDEX(Grades_Realms!$B$2:$B$43, B1339) -> Transcendent Dao · Perfected | D1339: =(A1339+1)^2.4 * 1.004^A1339 -> 6.6293156e+09 | E1339: =$I$2*(A1339+1)^1.9*1.003^A1339 -> 20657.377 | F1339: =(A1339+1)^1.12 -> 3174.1749 | G1339: =G1338+E1339 -> 4383000

Sheet Buildings_Master
A1: Era | B1: Building | C1: Category | D1: Function / Base Output | E1: Base Timber-eq | F1: Base Stone/Metal-eq | G1: Base Special-eq | H1: Cost @ Level L | I1: Time @ Level L | J1: Levels | K1: Grades
A2: 1 | B2: Chieftain's Hall | C2: HQ/Governance | D2: +1 queue slot / 8 grades | E2: 90 | F2: 80 | G2: 70 | H2: =E2&" × (L+1)^2.4 × 1.004^L (see Building_Levels)" -> 90 × (L+1)^2.4 × 1.004^L (see Building_Levels) | I2: base_time × (L+1)^1.9 × 1.003^L ÷ HQ_factor | J2: 0–1337 | K2: 42
A3: 1 | B3: Farm | C3: Extraction | D3: Grain 30/h base | E3: 45 | F3: 40 | G3: 30 | H3: =E3&" × (L+1)^2.4 × 1.004^L (see Building_Levels)" -> 45 × (L+1)^2.4 × 1.004^L (see Building_Levels) | I3: base_time × (L+1)^1.9 × 1.003^L ÷ HQ_factor | J3: 0–1337 | K3: 42
A4: 1 | B4: Fishery | C4: Extraction | D4: Fish 26/h | E4: 50 | F4: 30 | G4: 20 | H4: =E4&" × (L+1)^2.4 × 1.004^L (see Building_Levels)" -> 50 × (L+1)^2.4 × 1.004^L (see Building_Levels) | I4: base_time × (L+1)^1.9 × 1.003^L ÷ HQ_factor | J4: 0–1337 | K4: 42
A5: 1 | B5: Lumber Camp | C5: Extraction | D5: Timber 30/h | E5: 40 | F5: 50 | G5: 25 | H5: =E5&" × (L+1)^2.4 × 1.004^L (see Building_Levels)" -> 40 × (L+1)^2.4 × 1.004^L (see Building_Levels) | I5: base_time × (L+1)^1.9 × 1.003^L ÷ HQ_factor | J5: 0–1337 | K5: 42
A6: 1 | B6: Mine | C6: Extraction | D6: Ore 26/h | E6: 48 | F6: 60 | G6: 35 | H6: =E6&" × (L+1)^2.4 × 1.004^L (see Building_Levels)" -> 48 × (L+1)^2.4 × 1.004^L (see Building_Levels) | I6: base_time × (L+1)^1.9 × 1.003^L ÷ HQ_factor | J6: 0–1337 | K6: 42
A7: 1 | B7: Hunter's Lodge | C7: Extraction | D7: Hide 14/h | E7: 42 | F7: 32 | G7: 20 | H7: =E7&" × (L+1)^2.4 × 1.004^L (see Building_Levels)" -> 42 × (L+1)^2.4 × 1.004^L (see Building_Levels) | I7: base_time × (L+1)^1.9 × 1.003^L ÷ HQ_factor | J7: 0–1337 | K7: 42
A8: 1 | B8: Clay Pit | C8: Extraction | D8: Clay 20/h | E8: 38 | F8: 30 | G8: 18 | H8: =E8&" × (L+1)^2.4 × 1.004^L (see Building_Levels)" -> 38 × (L+1)^2.4 × 1.004^L (see Building_Levels) | I8: base_time × (L+1)^1.9 × 1.003^L ÷ HQ_factor | J8: 0–1337 | K8: 42
A9: 1 | B9: Herb Garden | C9: Extraction | D9: Spirit Herbs 6/h | E9: 40 | F9: 28 | G9: 22 | H9: =E9&" × (L+1)^2.4 × 1.004^L (see Building_Levels)" -> 40 × (L+1)^2.4 × 1.004^L (see Building_Levels) | I9: base_time × (L+1)^1.9 × 1.003^L ÷ HQ_factor | J9: 0–1337 | K9: 42
A10: 1 | B10: Apiary | C10: Extraction | D10: Honey (food+happiness) | E10: 35 | F10: 20 | G10: 15 | H10: =E10&" × (L+1)^2.4 × 1.004^L (see Building_Levels)" -> 35 × (L+1)^2.4 × 1.004^L (see Building_Levels) | I10: base_time × (L+1)^1.9 × 1.003^L ÷ HQ_factor | J10: 0–1337 | K10: 42
A11: 1 | B11: Orchard | C11: Extraction | D11: Fruit (food var.) | E11: 44 | F11: 26 | G11: 18 | H11: =E11&" × (L+1)^2.4 × 1.004^L (see Building_Levels)" -> 44 × (L+1)^2.4 × 1.004^L (see Building_Levels) | I11: base_time × (L+1)^1.9 × 1.003^L ÷ HQ_factor | J11: 0–1337 | K11: 42
A12: 1 | B12: Vegetable Garden | C12: Extraction | D12: Food 10/h | E12: 30 | F12: 18 | G12: 12 | H12: =E12&" × (L+1)^2.4 × 1.004^L (see Building_Levels)" -> 30 × (L+1)^2.4 × 1.004^L (see Building_Levels) | I12: base_time × (L+1)^1.9 × 1.003^L ÷ HQ_factor | J12: 0–1337 | K12: 42
A13: 1 | B13: Pig Pen | C13: Extraction | D13: Food 12/h | E13: 33 | F13: 22 | G13: 14 | H13: =E13&" × (L+1)^2.4 × 1.004^L (see Building_Levels)" -> 33 × (L+1)^2.4 × 1.004^L (see Building_Levels) | I13: base_time × (L+1)^1.9 × 1.003^L ÷ HQ_factor | J13: 0–1337 | K13: 42
... A484: 7 | B484: Dao Debate Hall | C484: Culture | D484: Cross-path diplomacy; Culture | E484: 1690 | F484: 1670 | G484: 1630 | H484: =E484&" × (L+1)^2.4 × 1.004^L (see Building_Levels)" -> 1690 × (L+1)^2.4 × 1.004^L (see Building_Levels) | I484: base_time × (L+1)^1.9 × 1.003^L ÷ HQ_factor | J484: 0–1337 | K484: 42
B486: Blue = design-input base costs (era-currency equivalents; map to era resources per Section 6 of the GDD). Every building: 1338 levels, grade breakthrough every 32 levels via Grade-Up Project (Grades_Realms sheet).

Sheet Level_Calculator
A1: Building name (type exactly as in Buildings_Master): | D1: Chieftain's Hall
A2: Base Timber-eq | B2: =INDEX(Buildings_Master!E:E, MATCH($D$1, Buildings_Master!B:B, 0)) -> 90 | C2: Base Stone/Metal-eq | D2: =INDEX(Buildings_Master!F:F, MATCH($D$1, Buildings_Master!B:B, 0)) -> 80 | E2: Base Special-eq | F2: =INDEX(Buildings_Master!G:G, MATCH($D$1, Buildings_Master!B:B, 0)) -> 70 | G2: Total climb 0→1337 (years): | H2: =SUM(F5:F1342)/8766 -> 500.00001
A4: Level | B4: Grade # | C4: Timber-eq Cost | D4: Stone/Metal-eq Cost | E4: Special-eq Cost | F4: Build Time (hours) | G4: Relative Output
A5: 0 | B5: =MIN(42, FLOOR(A5/32,1)+1) -> 1 | C5: =ROUND($B$2*(A5+1)^2.4*1.004^A5,0) -> 90 | D5: =ROUND($D$2*(A5+1)^2.4*1.004^A5,0) -> 80 | E5: =ROUND($F$2*(A5+1)^2.4*1.004^A5,0) -> 70 | F5: =ROUND(Building_Levels!$I$2*(A5+1)^1.9*1.003^A5,2) -> 0 | G5: =ROUND((A5+1)^1.12,1) -> 1
A6: 1 | B6: =MIN(42, FLOOR(A6/32,1)+1) -> 1 | C6: =ROUND($B$2*(A6+1)^2.4*1.004^A6,0) -> 477 | D6: =ROUND($D$2*(A6+1)^2.4*1.004^A6,0) -> 424 | E6: =ROUND($F$2*(A6+1)^2.4*1.004^A6,0) -> 371 | F6: =ROUND(Building_Levels!$I$2*(A6+1)^1.9*1.003^A6,2) -> 0 | G6: =ROUND((A6+1)^1.12,1) -> 2.2
A7: 2 | B7: =MIN(42, FLOOR(A7/32,1)+1) -> 1 | C7: =ROUND($B$2*(A7+1)^2.4*1.004^A7,0) -> 1267 | D7: =ROUND($D$2*(A7+1)^2.4*1.004^A7,0) -> 1126 | E7: =ROUND($F$2*(A7+1)^2.4*1.004^A7,0) -> 985 | F7: =ROUND(Building_Levels!$I$2*(A7+1)^1.9*1.003^A7,2) -> 0 | G7: =ROUND((A7+1)^1.12,1) -> 3.4
A8: 3 | B8: =MIN(42, FLOOR(A8/32,1)+1) -> 1 | C8: =ROUND($B$2*(A8+1)^2.4*1.004^A8,0) -> 2537 | D8: =ROUND($D$2*(A8+1)^2.4*1.004^A8,0) -> 2255 | E8: =ROUND($F$2*(A8+1)^2.4*1.004^A8,0) -> 1974 | F8: =ROUND(Building_Levels!$I$2*(A8+1)^1.9*1.003^A8,2) -> 0.01 | G8: =ROUND((A8+1)^1.12,1) -> 4.7
A9: 4 | B9: =MIN(42, FLOOR(A9/32,1)+1) -> 1 | C9: =ROUND($B$2*(A9+1)^2.4*1.004^A9,0) -> 4352 | D9: =ROUND($D$2*(A9+1)^2.4*1.004^A9,0) -> 3869 | E9: =ROUND($F$2*(A9+1)^2.4*1.004^A9,0) -> 3385 | F9: =ROUND(Building_Levels!$I$2*(A9+1)^1.9*1.003^A9,2) -> 0.01 | G9: =ROUND((A9+1)^1.12,1) -> 6.1
A10: 5 | B10: =MIN(42, FLOOR(A10/32,1)+1) -> 1 | C10: =ROUND($B$2*(A10+1)^2.4*1.004^A10,0) -> 6768 | D10: =ROUND($D$2*(A10+1)^2.4*1.004^A10,0) -> 6016 | E10: =ROUND($F$2*(A10+1)^2.4*1.004^A10,0) -> 5264 | F10: =ROUND(Building_Levels!$I$2*(A10+1)^1.9*1.003^A10,2) -> 0.01 | G10: =ROUND((A10+1)^1.12,1) -> 7.4
A11: 6 | B11: =MIN(42, FLOOR(A11/32,1)+1) -> 1 | C11: =ROUND($B$2*(A11+1)^2.4*1.004^A11,0) -> 9837 | D11: =ROUND($D$2*(A11+1)^2.4*1.004^A11,0) -> 8744 | E11: =ROUND($F$2*(A11+1)^2.4*1.004^A11,0) -> 7651 | F11: =ROUND(Building_Levels!$I$2*(A11+1)^1.9*1.003^A11,2) -> 0.02 | G11: =ROUND((A11+1)^1.12,1) -> 8.8
A12: 7 | B12: =MIN(42, FLOOR(A12/32,1)+1) -> 1 | C12: =ROUND($B$2*(A12+1)^2.4*1.004^A12,0) -> 13608 | D12: =ROUND($D$2*(A12+1)^2.4*1.004^A12,0) -> 12096 | E12: =ROUND($F$2*(A12+1)^2.4*1.004^A12,0) -> 10584 | F12: =ROUND(Building_Levels!$I$2*(A12+1)^1.9*1.003^A12,2) -> 0.02 | G12: =ROUND((A12+1)^1.12,1) -> 10.3
A13: 8 | B13: =MIN(42, FLOOR(A13/32,1)+1) -> 1 | C13: =ROUND($B$2*(A13+1)^2.4*1.004^A13,0) -> 18126 | D13: =ROUND($D$2*(A13+1)^2.4*1.004^A13,0) -> 16112 | E13: =ROUND($F$2*(A13+1)^2.4*1.004^A13,0) -> 14098 | F13: =ROUND(Building_Levels!$I$2*(A13+1)^1.9*1.003^A13,2) -> 0.03 | G13: =ROUND((A13+1)^1.12,1) -> 11.7
A14: 9 | B14: =MIN(42, FLOOR(A14/32,1)+1) -> 1 | C14: =ROUND($B$2*(A14+1)^2.4*1.004^A14,0) -> 23434 | D14: =ROUND($D$2*(A14+1)^2.4*1.004^A14,0) -> 20830 | E14: =ROUND($F$2*(A14+1)^2.4*1.004^A14,0) -> 18226 | F14: =ROUND(Building_Levels!$I$2*(A14+1)^1.9*1.003^A14,2) -> 0.04 | G14: =ROUND((A14+1)^1.12,1) -> 13.2
A15: 10 | B15: =MIN(42, FLOOR(A15/32,1)+1) -> 1 | C15: =ROUND($B$2*(A15+1)^2.4*1.004^A15,0) -> 29575 | D15: =ROUND($D$2*(A15+1)^2.4*1.004^A15,0) -> 26289 | E15: =ROUND($F$2*(A15+1)^2.4*1.004^A15,0) -> 23003 | F15: =ROUND(Building_Levels!$I$2*(A15+1)^1.9*1.003^A15,2) -> 0.04 | G15: =ROUND((A15+1)^1.12,1) -> 14.7
A16: 11 | B16: =MIN(42, FLOOR(A16/32,1)+1) -> 1 | C16: =ROUND($B$2*(A16+1)^2.4*1.004^A16,0) -> 36589 | D16: =ROUND($D$2*(A16+1)^2.4*1.004^A16,0) -> 32523 | E16: =ROUND($F$2*(A16+1)^2.4*1.004^A16,0) -> 28458 | F16: =ROUND(Building_Levels!$I$2*(A16+1)^1.9*1.003^A16,2) -> 0.05 | G16: =ROUND((A16+1)^1.12,1) -> 16.2
... A1342: 1337 | B1342: =MIN(42, FLOOR(A1342/32,1)+1) -> 42 | C1342: =ROUND($B$2*(A1342+1)^2.4*1.004^A1342,0) -> 596638408153 | D1342: =ROUND($D$2*(A1342+1)^2.4*1.004^A1342,0) -> 530345251691 | E1342: =ROUND($F$2*(A1342+1)^2.4*1.004^A1342,0) -> 464052095230 | F1342: =ROUND(Building_Levels!$I$2*(A1342+1)^1.9*1.003^A1342,2) -> 20657.38 | G1342: =ROUND((A1342+1)^1.12,1) -> 3174.2

Sheet Archetypes
A1: Key | B1: Era | C1: Archetype | D1: Role | E1: Base Atk | F1: Base Def | G1: Base HP | H1: Base Speed | I1: Base Upkeep | J1: Base Train (h) | L1: Train const (h per upkeep pt)
A2: 1|Militia | B2: 1 | C2: Militia | D2: Line Infantry | E2: 8 | F2: 14 | G2: 60 | H2: 18 | I2: 2 | J2: =ROUND(I2*$L$2,2) -> 0.81 | L2: =4383/(12*900) -> 0.40583333
A3: 1|Spearman | B3: 1 | C3: Spearman | D3: Anti-Cavalry | E3: 10 | F3: 22 | G3: 80 | H3: 16 | I3: 3 | J3: =ROUND(I3*$L$2,2) -> 1.22 | L3: Calibration: Mythic (12×) Path Avatar (upkeep 900) trains in 6 months = 4,383 h.
A4: 1|Axeman | B4: 1 | C4: Axeman | D4: Shock Infantry | E4: 22 | F4: 10 | G4: 85 | H4: 17 | I4: 3 | J4: =ROUND(I4*$L$2,2) -> 1.22
A5: 1|Slinger | B5: 1 | C5: Slinger | D5: Ranged | E5: 14 | F5: 6 | G5: 45 | H5: 18 | I5: 2 | J5: =ROUND(I5*$L$2,2) -> 0.81
A6: 1|Hunter-Archer | B6: 1 | C6: Hunter-Archer | D6: Ranged | E6: 18 | F6: 8 | G6: 50 | H6: 19 | I6: 3 | J6: =ROUND(I6*$L$2,2) -> 1.22
A7: 1|Raider | B7: 1 | C7: Raider | D7: Skirmisher | E7: 16 | F7: 8 | G7: 55 | H7: 26 | I7: 3 | J7: =ROUND(I7*$L$2,2) -> 1.22
A8: 1|Scout | B8: 1 | C8: Scout | D8: Recon | E8: 4 | F8: 4 | G8: 30 | H8: 34 | I8: 1 | J8: =ROUND(I8*$L$2,2) -> 0.41
A9: 1|Shield Bearer | B9: 1 | C9: Shield Bearer | D9: Screen | E9: 8 | F9: 26 | G9: 95 | H9: 15 | I9: 3 | J9: =ROUND(I9*$L$2,2) -> 1.22
A10: 1|Loot Carrier | B10: 1 | C10: Loot Carrier | D10: Logistics | E10: 2 | F10: 6 | G10: 50 | H10: 20 | I10: 2 | J10: =ROUND(I10*$L$2,2) -> 0.81
A11: 1|Chief Guard | B11: 1 | C11: Chief Guard | D11: Elite Shock | E11: 30 | F11: 20 | G11: 120 | H11: 17 | I11: 6 | J11: =ROUND(I11*$L$2,2) -> 2.44
A12: 1|Slave Levy | B12: 1 | C12: Slave Levy | D12: Line Infantry | E12: 6 | F12: 8 | G12: 50 | H12: 16 | I12: 1 | J12: =ROUND(I12*$L$2,2) -> 0.41
A13: 1|War Dog Pack | B13: 1 | C13: War Dog Pack | D13: Skirmisher | E13: 14 | F13: 6 | G13: 40 | H13: 30 | I13: 2 | J13: =ROUND(I13*$L$2,2) -> 0.81
A14: 1|Totem Warrior | B14: 1 | C14: Totem Warrior | D14: Elite Shock | E14: 26 | F14: 16 | G14: 105 | H14: 16 | I14: 5 | J14: =ROUND(I14*$L$2,2) -> 2.03
A15: 1|Stone Thrower | B15: 1 | C15: Stone Thrower | D15: Siege | E15: 20 | F15: 4 | G15: 60 | H15: 8 | I15: 4 | J15: =ROUND(I15*$L$2,2) -> 1.62
... A127: 7|Boundless Swarm | B127: 7 | C127: Boundless Swarm | D127: Drone | E127: 1900 | F127: 900 | G127: 7000 | H127: 80 | I127: 240 | J127: =ROUND(I127*$L$2,2) -> 97.4

Sheet Unit_Grades
A1: Grade | B1: Multiplier (Atk/Def/HP) | C1: Upkeep Mult | D1: Train Time Mult | E1: Unlock
A2: Mortal | B2: 1 | C2: 1 | D2: 1 | E2: Default
A3: Refined | B3: 1.35 | C3: 1.25 | D3: 1.5 | E3: Discipline grade ≥ 6 (Awakened Meridian ·Perfected)
A4: Elite | B4: 1.8 | C4: 1.6 | D4: 2.5 | E4: Grade ≥ 12 + Warfare rank 5
A5: Ascendant | B5: 2.4 | C5: 2.1 | D5: 4 | E5: Grade ≥ 21 + cultivation realm Sovereign
A6: Transcendent | B6: 3.2 | C6: 2.8 | D6: 7 | E6: Grade ≥ 30 + path chosen
A7: Mythic | B7: 4.2 | C7: 3.7 | D7: 12 | E7: Grade ≥ 39 + relic core (rare drop)

Sheet Unit_Paths
A1: Path | B1: Atk Mod | C1: Def Mod | D1: HP Mod | E1: Speed Mod | F1: Identity
A2: Orthodox (Balanced) | B2: 1 | C2: 1 | D2: 1 | E2: 1 | F2: No twist; cheapest to unlock
A3: Asura (Offense) | B3: 1.2 | C3: 0.85 | D3: 0.95 | E3: 1.05 | F3: Warfare-heavy identity; unlocked by battle deeds
A4: Guardian (Defense) | B4: 0.85 | C4: 1.25 | D4: 1.15 | E4: 0.92 | F4: Construction/defense identity; unlocked by defenses held

Sheet Units_Master
A1: Era | B1: Unit Name | C1: Archetype | D1: Key | E1: Path | F1: Grade | G1: Role | H1: Atk | I1: Def | J1: HP | K1: Speed | L1: Upkeep | M1: Train Time (h) | N1: Train Time (days)
A2: 1 | B2: Militia | C2: Militia | D2: =A2&"|"&C2 -> 1|Militia | E2: Orthodox (Balanced) | F2: Mortal | G2: =INDEX(Archetypes!$D$2:$D$127, MATCH(D2, Archetypes!$A$2:$A$127, 0)) -> Line Infantry | H2: =ROUND(INDEX(Archetypes!$E$2:$E$127, MATCH(D2, Archetypes!$A$2:$A$127, 0))*INDEX(Unit_Grades!$B$2:$B$7, MATCH(F2, Unit_Grades!$A$2:$A$7, 0))*INDEX(Unit_Paths!$B$2:$B$4, MATCH(E2, Unit_Paths!$A$2:$A$4, 0)),1) -> 8 | I2: =ROUND(INDEX(Archetypes!$F$2:$F$127, MATCH(D2, Archetypes!$A$2:$A$127, 0))*INDEX(Unit_Grades!$B$2:$B$7, MATCH(F2, Unit_Grades!$A$2:$A$7, 0))*INDEX(Unit_Paths!$C$2:$C$4, MATCH(E2, Unit_Paths!$A$2:$A$4, 0)),1) -> 14 | J2: =ROUND(INDEX(Archetypes!$G$2:$G$127, MATCH(D2, Archetypes!$A$2:$A$127, 0))*INDEX(Unit_Grades!$B$2:$B$7, MATCH(F2, Unit_Grades!$A$2:$A$7, 0))*INDEX(Unit_Paths!$D$2:$D$4, MATCH(E2, Unit_Paths!$A$2:$A$4, 0)),0) -> 60 | K2: =ROUND(INDEX(Archetypes!$H$2:$H$127, MATCH(D2, Archetypes!$A$2:$A$127, 0))*INDEX(Unit_Paths!$E$2:$E$4, MATCH(E2, Unit_Paths!$A$2:$A$4, 0)),1) -> 18 | L2: =ROUND(INDEX(Archetypes!$I$2:$I$127, MATCH(D2, Archetypes!$A$2:$A$127, 0))*INDEX(Unit_Grades!$C$2:$C$7, MATCH(F2, Unit_Grades!$A$2:$A$7, 0)),1) -> 2 | M2: =ROUND(INDEX(Archetypes!$J$2:$J$127, MATCH(D2, Archetypes!$A$2:$A$127, 0))*INDEX(Unit_Grades!$D$2:$D$7, MATCH(F2, Unit_Grades!$A$2:$A$7, 0)),1) -> 0.8 | N2: =ROUND(M2/24,2) -> 0.03
A3: 1 | B3: Refined Militia | C3: Militia | D3: =A3&"|"&C3 -> 1|Militia | E3: Orthodox (Balanced) | F3: Refined | G3: =INDEX(Archetypes!$D$2:$D$127, MATCH(D3, Archetypes!$A$2:$A$127, 0)) -> Line Infantry | H3: =ROUND(INDEX(Archetypes!$E$2:$E$127, MATCH(D3, Archetypes!$A$2:$A$127, 0))*INDEX(Unit_Grades!$B$2:$B$7, MATCH(F3, Unit_Grades!$A$2:$A$7, 0))*INDEX(Unit_Paths!$B$2:$B$4, MATCH(E3, Unit_Paths!$A$2:$A$4, 0)),1) -> 10.8 | I3: =ROUND(INDEX(Archetypes!$F$2:$F$127, MATCH(D3, Archetypes!$A$2:$A$127, 0))*INDEX(Unit_Grades!$B$2:$B$7, MATCH(F3, Unit_Grades!$A$2:$A$7, 0))*INDEX(Unit_Paths!$C$2:$C$4, MATCH(E3, Unit_Paths!$A$2:$A$4, 0)),1) -> 18.9 | J3: =ROUND(INDEX(Archetypes!$G$2:$G$127, MATCH(D3, Archetypes!$A$2:$A$127, 0))*INDEX(Unit_Grades!$B$2:$B$7, MATCH(F3, Unit_Grades!$A$2:$A$7, 0))*INDEX(Unit_Paths!$D$2:$D$4, MATCH(E3, Unit_Paths!$A$2:$A$4, 0)),0) -> 81 | K3: =ROUND(INDEX(Archetypes!$H$2:$H$127, MATCH(D3, Archetypes!$A$2:$A$127, 0))*INDEX(Unit_Paths!$E$2:$E$4, MATCH(E3, Unit_Paths!$A$2:$A$4, 0)),1) -> 18 | L3: =ROUND(INDEX(Archetypes!$I$2:$I$127, MATCH(D3, Archetypes!$A$2:$A$127, 0))*INDEX(Unit_Grades!$C$2:$C$7, MATCH(F3, Unit_Grades!$A$2:$A$7, 0)),1) -> 2.5 | M3: =ROUND(INDEX(Archetypes!$J$2:$J$127, MATCH(D3, Archetypes!$A$2:$A$127, 0))*INDEX(Unit_Grades!$D$2:$D$7, MATCH(F3, Unit_Grades!$A$2:$A$7, 0)),1) -> 1.2 | N3: =ROUND(M3/24,2) -> 0.05
A4: 1 | B4: Elite Militia | C4: Militia | D4: =A4&"|"&C4 -> 1|Militia | E4: Orthodox (Balanced) | F4: Elite | G4: =INDEX(Archetypes!$D$2:$D$127, MATCH(D4, Archetypes!$A$2:$A$127, 0)) -> Line Infantry | H4: =ROUND(INDEX(Archetypes!$E$2:$E$127, MATCH(D4, Archetypes!$A$2:$A$127, 0))*INDEX(Unit_Grades!$B$2:$B$7, MATCH(F4, Unit_Grades!$A$2:$A$7, 0))*INDEX(Unit_Paths!$B$2:$B$4, MATCH(E4, Unit_Paths!$A$2:$A$4, 0)),1) -> 14.4 | I4: =ROUND(INDEX(Archetypes!$F$2:$F$127, MATCH(D4, Archetypes!$A$2:$A$127, 0))*INDEX(Unit_Grades!$B$2:$B$7, MATCH(F4, Unit_Grades!$A$2:$A$7, 0))*INDEX(Unit_Paths!$C$2:$C$4, MATCH(E4, Unit_Paths!$A$2:$A$4, 0)),1) -> 25.2 | J4: =ROUND(INDEX(Archetypes!$G$2:$G$127, MATCH(D4, Archetypes!$A$2:$A$127, 0))*INDEX(Unit_Grades!$B$2:$B$7, MATCH(F4, Unit_Grades!$A$2:$A$7, 0))*INDEX(Unit_Paths!$D$2:$D$4, MATCH(E4, Unit_Paths!$A$2:$A$4, 0)),0) -> 108 | K4: =ROUND(INDEX(Archetypes!$H$2:$H$127, MATCH(D4, Archetypes!$A$2:$A$127, 0))*INDEX(Unit_Paths!$E$2:$E$4, MATCH(E4, Unit_Paths!$A$2:$A$4, 0)),1) -> 18 | L4: =ROUND(INDEX(Archetypes!$I$2:$I$127, MATCH(D4, Archetypes!$A$2:$A$127, 0))*INDEX(Unit_Grades!$C$2:$C$7, MATCH(F4, Unit_Grades!$A$2:$A$7, 0)),1) -> 3.2 | M4: =ROUND(INDEX(Archetypes!$J$2:$J$127, MATCH(D4, Archetypes!$A$2:$A$127, 0))*INDEX(Unit_Grades!$D$2:$D$7, MATCH(F4, Unit_Grades!$A$2:$A$7, 0)),1) -> 2 | N4: =ROUND(M4/24,2) -> 0.08
A5: 1 | B5: Ascendant Militia | C5: Militia | D5: =A5&"|"&C5 -> 1|Militia | E5: Orthodox (Balanced) | F5: Ascendant | G5: =INDEX(Archetypes!$D$2:$D$127, MATCH(D5, Archetypes!$A$2:$A$127, 0)) -> Line Infantry | H5: =ROUND(INDEX(Archetypes!$E$2:$E$127, MATCH(D5, Archetypes!$A$2:$A$127, 0))*INDEX(Unit_Grades!$B$2:$B$7, MATCH(F5, Unit_Grades!$A$2:$A$7, 0))*INDEX(Unit_Paths!$B$2:$B$4, MATCH(E5, Unit_Paths!$A$2:$A$4, 0)),1) -> 19.2 | I5: =ROUND(INDEX(Archetypes!$F$2:$F$127, MATCH(D5, Archetypes!$A$2:$A$127, 0))*INDEX(Unit_Grades!$B$2:$B$7, MATCH(F5, Unit_Grades!$A$2:$A$7, 0))*INDEX(Unit_Paths!$C$2:$C$4, MATCH(E5, Unit_Paths!$A$2:$A$4, 0)),1) -> 33.6 | J5: =ROUND(INDEX(Archetypes!$G$2:$G$127, MATCH(D5, Archetypes!$A$2:$A$127, 0))*INDEX(Unit_Grades!$B$2:$B$7, MATCH(F5, Unit_Grades!$A$2:$A$7, 0))*INDEX(Unit_Paths!$D$2:$D$4, MATCH(E5, Unit_Paths!$A$2:$A$4, 0)),0) -> 144 | K5: =ROUND(INDEX(Archetypes!$H$2:$H$127, MATCH(D5, Archetypes!$A$2:$A$127, 0))*INDEX(Unit_Paths!$E$2:$E$4, MATCH(E5, Unit_Paths!$A$2:$A$4, 0)),1) -> 18 | L5: =ROUND(INDEX(Archetypes!$I$2:$I$127, MATCH(D5, Archetypes!$A$2:$A$127, 0))*INDEX(Unit_Grades!$C$2:$C$7, MATCH(F5, Unit_Grades!$A$2:$A$7, 0)),1) -> 4.2 | M5: =ROUND(INDEX(Archetypes!$J$2:$J$127, MATCH(D5, Archetypes!$A$2:$A$127, 0))*INDEX(Unit_Grades!$D$2:$D$7, MATCH(F5, Unit_Grades!$A$2:$A$7, 0)),1) -> 3.2 | N5: =ROUND(M5/24,2) -> 0.13
A6: 1 | B6: Transcendent Militia | C6: Militia | D6: =A6&"|"&C6 -> 1|Militia | E6: Orthodox (Balanced) | F6: Transcendent | G6: =INDEX(Archetypes!$D$2:$D$127, MATCH(D6, Archetypes!$A$2:$A$127, 0)) -> Line Infantry | H6: =ROUND(INDEX(Archetypes!$E$2:$E$127, MATCH(D6, Archetypes!$A$2:$A$127, 0))*INDEX(Unit_Grades!$B$2:$B$7, MATCH(F6, Unit_Grades!$A$2:$A$7, 0))*INDEX(Unit_Paths!$B$2:$B$4, MATCH(E6, Unit_Paths!$A$2:$A$4, 0)),1) -> 25.6 | I6: =ROUND(INDEX(Archetypes!$F$2:$F$127, MATCH(D6, Archetypes!$A$2:$A$127, 0))*INDEX(Unit_Grades!$B$2:$B$7, MATCH(F6, Unit_Grades!$A$2:$A$7, 0))*INDEX(Unit_Paths!$C$2:$C$4, MATCH(E6, Unit_Paths!$A$2:$A$4, 0)),1) -> 44.8 | J6: =ROUND(INDEX(Archetypes!$G$2:$G$127, MATCH(D6, Archetypes!$A$2:$A$127, 0))*INDEX(Unit_Grades!$B$2:$B$7, MATCH(F6, Unit_Grades!$A$2:$A$7, 0))*INDEX(Unit_Paths!$D$2:$D$4, MATCH(E6, Unit_Paths!$A$2:$A$4, 0)),0) -> 192 | K6: =ROUND(INDEX(Archetypes!$H$2:$H$127, MATCH(D6, Archetypes!$A$2:$A$127, 0))*INDEX(Unit_Paths!$E$2:$E$4, MATCH(E6, Unit_Paths!$A$2:$A$4, 0)),1) -> 18 | L6: =ROUND(INDEX(Archetypes!$I$2:$I$127, MATCH(D6, Archetypes!$A$2:$A$127, 0))*INDEX(Unit_Grades!$C$2:$C$7, MATCH(F6, Unit_Grades!$A$2:$A$7, 0)),1) -> 5.6 | M6: =ROUND(INDEX(Archetypes!$J$2:$J$127, MATCH(D6, Archetypes!$A$2:$A$127, 0))*INDEX(Unit_Grades!$D$2:$D$7, MATCH(F6, Unit_Grades!$A$2:$A$7, 0)),1) -> 5.7 | N6: =ROUND(M6/24,2) -> 0.24
A7: 1 | B7: Mythic Militia | C7: Militia | D7: =A7&"|"&C7 -> 1|Militia | E7: Orthodox (Balanced) | F7: Mythic | G7: =INDEX(Archetypes!$D$2:$D$127, MATCH(D7, Archetypes!$A$2:$A$127, 0)) -> Line Infantry | H7: =ROUND(INDEX(Archetypes!$E$2:$E$127, MATCH(D7, Archetypes!$A$2:$A$127, 0))*INDEX(Unit_Grades!$B$2:$B$7, MATCH(F7, Unit_Grades!$A$2:$A$7, 0))*INDEX(Unit_Paths!$B$2:$B$4, MATCH(E7, Unit_Paths!$A$2:$A$4, 0)),1) -> 33.6 | I7: =ROUND(INDEX(Archetypes!$F$2:$F$127, MATCH(D7, Archetypes!$A$2:$A$127, 0))*INDEX(Unit_Grades!$B$2:$B$7, MATCH(F7, Unit_Grades!$A$2:$A$7, 0))*INDEX(Unit_Paths!$C$2:$C$4, MATCH(E7, Unit_Paths!$A$2:$A$4, 0)),1) -> 58.8 | J7: =ROUND(INDEX(Archetypes!$G$2:$G$127, MATCH(D7, Archetypes!$A$2:$A$127, 0))*INDEX(Unit_Grades!$B$2:$B$7, MATCH(F7, Unit_Grades!$A$2:$A$7, 0))*INDEX(Unit_Paths!$D$2:$D$4, MATCH(E7, Unit_Paths!$A$2:$A$4, 0)),0) -> 252 | K7: =ROUND(INDEX(Archetypes!$H$2:$H$127, MATCH(D7, Archetypes!$A$2:$A$127, 0))*INDEX(Unit_Paths!$E$2:$E$4, MATCH(E7, Unit_Paths!$A$2:$A$4, 0)),1) -> 18 | L7: =ROUND(INDEX(Archetypes!$I$2:$I$127, MATCH(D7, Archetypes!$A$2:$A$127, 0))*INDEX(Unit_Grades!$C$2:$C$7, MATCH(F7, Unit_Grades!$A$2:$A$7, 0)),1) -> 7.4 | M7: =ROUND(INDEX(Archetypes!$J$2:$J$127, MATCH(D7, Archetypes!$A$2:$A$127, 0))*INDEX(Unit_Grades!$D$2:$D$7, MATCH(F7, Unit_Grades!$A$2:$A$7, 0)),1) -> 9.7 | N7: =ROUND(M7/24,2) -> 0.4
A8: 1 | B8: Asura Militia | C8: Militia | D8: =A8&"|"&C8 -> 1|Militia | E8: Asura (Offense) | F8: Mortal | G8: =INDEX(Archetypes!$D$2:$D$127, MATCH(D8, Archetypes!$A$2:$A$127, 0)) -> Line Infantry | H8: =ROUND(INDEX(Archetypes!$E$2:$E$127, MATCH(D8, Archetypes!$A$2:$A$127, 0))*INDEX(Unit_Grades!$B$2:$B$7, MATCH(F8, Unit_Grades!$A$2:$A$7, 0))*INDEX(Unit_Paths!$B$2:$B$4, MATCH(E8, Unit_Paths!$A$2:$A$4, 0)),1) -> 9.6 | I8: =ROUND(INDEX(Archetypes!$F$2:$F$127, MATCH(D8, Archetypes!$A$2:$A$127, 0))*INDEX(Unit_Grades!$B$2:$B$7, MATCH(F8, Unit_Grades!$A$2:$A$7, 0))*INDEX(Unit_Paths!$C$2:$C$4, MATCH(E8, Unit_Paths!$A$2:$A$4, 0)),1) -> 11.9 | J8: =ROUND(INDEX(Archetypes!$G$2:$G$127, MATCH(D8, Archetypes!$A$2:$A$127, 0))*INDEX(Unit_Grades!$B$2:$B$7, MATCH(F8, Unit_Grades!$A$2:$A$7, 0))*INDEX(Unit_Paths!$D$2:$D$4, MATCH(E8, Unit_Paths!$A$2:$A$4, 0)),0) -> 57 | K8: =ROUND(INDEX(Archetypes!$H$2:$H$127, MATCH(D8, Archetypes!$A$2:$A$127, 0))*INDEX(Unit_Paths!$E$2:$E$4, MATCH(E8, Unit_Paths!$A$2:$A$4, 0)),1) -> 18.9 | L8: =ROUND(INDEX(Archetypes!$I$2:$I$127, MATCH(D8, Archetypes!$A$2:$A$127, 0))*INDEX(Unit_Grades!$C$2:$C$7, MATCH(F8, Unit_Grades!$A$2:$A$7, 0)),1) -> 2 | M8: =ROUND(INDEX(Archetypes!$J$2:$J$127, MATCH(D8, Archetypes!$A$2:$A$127, 0))*INDEX(Unit_Grades!$D$2:$D$7, MATCH(F8, Unit_Grades!$A$2:$A$7, 0)),1) -> 0.8 | N8: =ROUND(M8/24,2) -> 0.03
A9: 1 | B9: Refined Asura Militia | C9: Militia | D9: =A9&"|"&C9 -> 1|Militia | E9: Asura (Offense) | F9: Refined | G9: =INDEX(Archetypes!$D$2:$D$127, MATCH(D9, Archetypes!$A$2:$A$127, 0)) -> Line Infantry | H9: =ROUND(INDEX(Archetypes!$E$2:$E$127, MATCH(D9, Archetypes!$A$2:$A$127, 0))*INDEX(Unit_Grades!$B$2:$B$7, MATCH(F9, Unit_Grades!$A$2:$A$7, 0))*INDEX(Unit_Paths!$B$2:$B$4, MATCH(E9, Unit_Paths!$A$2:$A$4, 0)),1) -> 13 | I9: =ROUND(INDEX(Archetypes!$F$2:$F$127, MATCH(D9, Archetypes!$A$2:$A$127, 0))*INDEX(Unit_Grades!$B$2:$B$7, MATCH(F9, Unit_Grades!$A$2:$A$7, 0))*INDEX(Unit_Paths!$C$2:$C$4, MATCH(E9, Unit_Paths!$A$2:$A$4, 0)),1) -> 16.1 | J9: =ROUND(INDEX(Archetypes!$G$2:$G$127, MATCH(D9, Archetypes!$A$2:$A$127, 0))*INDEX(Unit_Grades!$B$2:$B$7, MATCH(F9, Unit_Grades!$A$2:$A$7, 0))*INDEX(Unit_Paths!$D$2:$D$4, MATCH(E9, Unit_Paths!$A$2:$A$4, 0)),0) -> 77 | K9: =ROUND(INDEX(Archetypes!$H$2:$H$127, MATCH(D9, Archetypes!$A$2:$A$127, 0))*INDEX(Unit_Paths!$E$2:$E$4, MATCH(E9, Unit_Paths!$A$2:$A$4, 0)),1) -> 18.9 | L9: =ROUND(INDEX(Archetypes!$I$2:$I$127, MATCH(D9, Archetypes!$A$2:$A$127, 0))*INDEX(Unit_Grades!$C$2:$C$7, MATCH(F9, Unit_Grades!$A$2:$A$7, 0)),1) -> 2.5 | M9: =ROUND(INDEX(Archetypes!$J$2:$J$127, MATCH(D9, Archetypes!$A$2:$A$127, 0))*INDEX(Unit_Grades!$D$2:$D$7, MATCH(F9, Unit_Grades!$A$2:$A$7, 0)),1) -> 1.2 | N9: =ROUND(M9/24,2) -> 0.05
A10: 1 | B10: Elite Asura Militia | C10: Militia | D10: =A10&"|"&C10 -> 1|Militia | E10: Asura (Offense) | F10: Elite | G10: =INDEX(Archetypes!$D$2:$D$127, MATCH(D10, Archetypes!$A$2:$A$127, 0)) -> Line Infantry | H10: =ROUND(INDEX(Archetypes!$E$2:$E$127, MATCH(D10, Archetypes!$A$2:$A$127, 0))*INDEX(Unit_Grades!$B$2:$B$7, MATCH(F10, Unit_Grades!$A$2:$A$7, 0))*INDEX(Unit_Paths!$B$2:$B$4, MATCH(E10, Unit_Paths!$A$2:$A$4, 0)),1) -> 17.3 | I10: =ROUND(INDEX(Archetypes!$F$2:$F$127, MATCH(D10, Archetypes!$A$2:$A$127, 0))*INDEX(Unit_Grades!$B$2:$B$7, MATCH(F10, Unit_Grades!$A$2:$A$7, 0))*INDEX(Unit_Paths!$C$2:$C$4, MATCH(E10, Unit_Paths!$A$2:$A$4, 0)),1) -> 21.4 | J10: =ROUND(INDEX(Archetypes!$G$2:$G$127, MATCH(D10, Archetypes!$A$2:$A$127, 0))*INDEX(Unit_Grades!$B$2:$B$7, MATCH(F10, Unit_Grades!$A$2:$A$7, 0))*INDEX(Unit_Paths!$D$2:$D$4, MATCH(E10, Unit_Paths!$A$2:$A$4, 0)),0) -> 103 | K10: =ROUND(INDEX(Archetypes!$H$2:$H$127, MATCH(D10, Archetypes!$A$2:$A$127, 0))*INDEX(Unit_Paths!$E$2:$E$4, MATCH(E10, Unit_Paths!$A$2:$A$4, 0)),1) -> 18.9 | L10: =ROUND(INDEX(Archetypes!$I$2:$I$127, MATCH(D10, Archetypes!$A$2:$A$127, 0))*INDEX(Unit_Grades!$C$2:$C$7, MATCH(F10, Unit_Grades!$A$2:$A$7, 0)),1) -> 3.2 | M10: =ROUND(INDEX(Archetypes!$J$2:$J$127, MATCH(D10, Archetypes!$A$2:$A$127, 0))*INDEX(Unit_Grades!$D$2:$D$7, MATCH(F10, Unit_Grades!$A$2:$A$7, 0)),1) -> 2 | N10: =ROUND(M10/24,2) -> 0.08
A11: 1 | B11: Ascendant Asura Militia | C11: Militia | D11: =A11&"|"&C11 -> 1|Militia | E11: Asura (Offense) | F11: Ascendant | G11: =INDEX(Archetypes!$D$2:$D$127, MATCH(D11, Archetypes!$A$2:$A$127, 0)) -> Line Infantry | H11: =ROUND(INDEX(Archetypes!$E$2:$E$127, MATCH(D11, Archetypes!$A$2:$A$127, 0))*INDEX(Unit_Grades!$B$2:$B$7, MATCH(F11, Unit_Grades!$A$2:$A$7, 0))*INDEX(Unit_Paths!$B$2:$B$4, MATCH(E11, Unit_Paths!$A$2:$A$4, 0)),1) -> 23 | I11: =ROUND(INDEX(Archetypes!$F$2:$F$127, MATCH(D11, Archetypes!$A$2:$A$127, 0))*INDEX(Unit_Grades!$B$2:$B$7, MATCH(F11, Unit_Grades!$A$2:$A$7, 0))*INDEX(Unit_Paths!$C$2:$C$4, MATCH(E11, Unit_Paths!$A$2:$A$4, 0)),1) -> 28.6 | J11: =ROUND(INDEX(Archetypes!$G$2:$G$127, MATCH(D11, Archetypes!$A$2:$A$127, 0))*INDEX(Unit_Grades!$B$2:$B$7, MATCH(F11, Unit_Grades!$A$2:$A$7, 0))*INDEX(Unit_Paths!$D$2:$D$4, MATCH(E11, Unit_Paths!$A$2:$A$4, 0)),0) -> 137 | K11: =ROUND(INDEX(Archetypes!$H$2:$H$127, MATCH(D11, Archetypes!$A$2:$A$127, 0))*INDEX(Unit_Paths!$E$2:$E$4, MATCH(E11, Unit_Paths!$A$2:$A$4, 0)),1) -> 18.9 | L11: =ROUND(INDEX(Archetypes!$I$2:$I$127, MATCH(D11, Archetypes!$A$2:$A$127, 0))*INDEX(Unit_Grades!$C$2:$C$7, MATCH(F11, Unit_Grades!$A$2:$A$7, 0)),1) -> 4.2 | M11: =ROUND(INDEX(Archetypes!$J$2:$J$127, MATCH(D11, Archetypes!$A$2:$A$127, 0))*INDEX(Unit_Grades!$D$2:$D$7, MATCH(F11, Unit_Grades!$A$2:$A$7, 0)),1) -> 3.2 | N11: =ROUND(M11/24,2) -> 0.13
A12: 1 | B12: Transcendent Asura Militia | C12: Militia | D12: =A12&"|"&C12 -> 1|Militia | E12: Asura (Offense) | F12: Transcendent | G12: =INDEX(Archetypes!$D$2:$D$127, MATCH(D12, Archetypes!$A$2:$A$127, 0)) -> Line Infantry | H12: =ROUND(INDEX(Archetypes!$E$2:$E$127, MATCH(D12, Archetypes!$A$2:$A$127, 0))*INDEX(Unit_Grades!$B$2:$B$7, MATCH(F12, Unit_Grades!$A$2:$A$7, 0))*INDEX(Unit_Paths!$B$2:$B$4, MATCH(E12, Unit_Paths!$A$2:$A$4, 0)),1) -> 30.7 | I12: =ROUND(INDEX(Archetypes!$F$2:$F$127, MATCH(D12, Archetypes!$A$2:$A$127, 0))*INDEX(Unit_Grades!$B$2:$B$7, MATCH(F12, Unit_Grades!$A$2:$A$7, 0))*INDEX(Unit_Paths!$C$2:$C$4, MATCH(E12, Unit_Paths!$A$2:$A$4, 0)),1) -> 38.1 | J12: =ROUND(INDEX(Archetypes!$G$2:$G$127, MATCH(D12, Archetypes!$A$2:$A$127, 0))*INDEX(Unit_Grades!$B$2:$B$7, MATCH(F12, Unit_Grades!$A$2:$A$7, 0))*INDEX(Unit_Paths!$D$2:$D$4, MATCH(E12, Unit_Paths!$A$2:$A$4, 0)),0) -> 182 | K12: =ROUND(INDEX(Archetypes!$H$2:$H$127, MATCH(D12, Archetypes!$A$2:$A$127, 0))*INDEX(Unit_Paths!$E$2:$E$4, MATCH(E12, Unit_Paths!$A$2:$A$4, 0)),1) -> 18.9 | L12: =ROUND(INDEX(Archetypes!$I$2:$I$127, MATCH(D12, Archetypes!$A$2:$A$127, 0))*INDEX(Unit_Grades!$C$2:$C$7, MATCH(F12, Unit_Grades!$A$2:$A$7, 0)),1) -> 5.6 | M12: =ROUND(INDEX(Archetypes!$J$2:$J$127, MATCH(D12, Archetypes!$A$2:$A$127, 0))*INDEX(Unit_Grades!$D$2:$D$7, MATCH(F12, Unit_Grades!$A$2:$A$7, 0)),1) -> 5.7 | N12: =ROUND(M12/24,2) -> 0.24
A13: 1 | B13: Mythic Asura Militia | C13: Militia | D13: =A13&"|"&C13 -> 1|Militia | E13: Asura (Offense) | F13: Mythic | G13: =INDEX(Archetypes!$D$2:$D$127, MATCH(D13, Archetypes!$A$2:$A$127, 0)) -> Line Infantry | H13: =ROUND(INDEX(Archetypes!$E$2:$E$127, MATCH(D13, Archetypes!$A$2:$A$127, 0))*INDEX(Unit_Grades!$B$2:$B$7, MATCH(F13, Unit_Grades!$A$2:$A$7, 0))*INDEX(Unit_Paths!$B$2:$B$4, MATCH(E13, Unit_Paths!$A$2:$A$4, 0)),1) -> 40.3 | I13: =ROUND(INDEX(Archetypes!$F$2:$F$127, MATCH(D13, Archetypes!$A$2:$A$127, 0))*INDEX(Unit_Grades!$B$2:$B$7, MATCH(F13, Unit_Grades!$A$2:$A$7, 0))*INDEX(Unit_Paths!$C$2:$C$4, MATCH(E13, Unit_Paths!$A$2:$A$4, 0)),1) -> 50 | J13: =ROUND(INDEX(Archetypes!$G$2:$G$127, MATCH(D13, Archetypes!$A$2:$A$127, 0))*INDEX(Unit_Grades!$B$2:$B$7, MATCH(F13, Unit_Grades!$A$2:$A$7, 0))*INDEX(Unit_Paths!$D$2:$D$4, MATCH(E13, Unit_Paths!$A$2:$A$4, 0)),0) -> 239 | K13: =ROUND(INDEX(Archetypes!$H$2:$H$127, MATCH(D13, Archetypes!$A$2:$A$127, 0))*INDEX(Unit_Paths!$E$2:$E$4, MATCH(E13, Unit_Paths!$A$2:$A$4, 0)),1) -> 18.9 | L13: =ROUND(INDEX(Archetypes!$I$2:$I$127, MATCH(D13, Archetypes!$A$2:$A$127, 0))*INDEX(Unit_Grades!$C$2:$C$7, MATCH(F13, Unit_Grades!$A$2:$A$7, 0)),1) -> 7.4 | M13: =ROUND(INDEX(Archetypes!$J$2:$J$127, MATCH(D13, Archetypes!$A$2:$A$127, 0))*INDEX(Unit_Grades!$D$2:$D$7, MATCH(F13, Unit_Grades!$A$2:$A$7, 0)),1) -> 9.7 | N13: =ROUND(M13/24,2) -> 0.4
... A2269: 7 | B2269: Mythic Guardian Boundless Swarm | C2269: Boundless Swarm | D2269: =A2269&"|"&C2269 -> 7|Boundless Swarm | E2269: Guardian (Defense) | F2269: Mythic | G2269: =INDEX(Archetypes!$D$2:$D$127, MATCH(D2269, Archetypes!$A$2:$A$127, 0)) -> Drone | H2269: =ROUND(INDEX(Archetypes!$E$2:$E$127, MATCH(D2269, Archetypes!$A$2:$A$127, 0))*INDEX(Unit_Grades!$B$2:$B$7, MATCH(F2269, Unit_Grades!$A$2:$A$7, 0))*INDEX(Unit_Paths!$B$2:$B$4, MATCH(E2269, Unit_Paths!$A$2:$A$4, 0)),1) -> 6783 | I2269: =ROUND(INDEX(Archetypes!$F$2:$F$127, MATCH(D2269, Archetypes!$A$2:$A$127, 0))*INDEX(Unit_Grades!$B$2:$B$7, MATCH(F2269, Unit_Grades!$A$2:$A$7, 0))*INDEX(Unit_Paths!$C$2:$C$4, MATCH(E2269, Unit_Paths!$A$2:$A$4, 0)),1) -> 4725 | J2269: =ROUND(INDEX(Archetypes!$G$2:$G$127, MATCH(D2269, Archetypes!$A$2:$A$127, 0))*INDEX(Unit_Grades!$B$2:$B$7, MATCH(F2269, Unit_Grades!$A$2:$A$7, 0))*INDEX(Unit_Paths!$D$2:$D$4, MATCH(E2269, Unit_Paths!$A$2:$A$4, 0)),0) -> 33810 | K2269: =ROUND(INDEX(Archetypes!$H$2:$H$127, MATCH(D2269, Archetypes!$A$2:$A$127, 0))*INDEX(Unit_Paths!$E$2:$E$4, MATCH(E2269, Unit_Paths!$A$2:$A$4, 0)),1) -> 73.6 | L2269: =ROUND(INDEX(Archetypes!$I$2:$I$127, MATCH(D2269, Archetypes!$A$2:$A$127, 0))*INDEX(Unit_Grades!$C$2:$C$7, MATCH(F2269, Unit_Grades!$A$2:$A$7, 0)),1) -> 888 | M2269: =ROUND(INDEX(Archetypes!$J$2:$J$127, MATCH(D2269, Archetypes!$A$2:$A$127, 0))*INDEX(Unit_Grades!$D$2:$D$7, MATCH(F2269, Unit_Grades!$A$2:$A$7, 0)),1) -> 1168.8 | N2269: =ROUND(M2269/24,2) -> 48.7

Sheet Counter_Matrix
A1: Attacker role ↓ / Defender role → | B1: Line Infantry | C1: Anti-Cavalry | D1: Shock Infantry | E1: Ranged | F1: Skirmisher | G1: Shock Cavalry | H1: Elite Shock | I1: Screen | J1: Siege | K1: Recon | L1: Agent | M1: Logistics | N1: Support | O1: Armor | P1: Anti-Armor | Q1: Anti-Infantry | R1: Anti-Air | S1: Air Superiority | T1: Air Strike | U1: Naval Raider | V1: Naval Escort | W1: Naval Logistics | X1: Capital | Y1: Line Warship | Z1: Carrier | AA1: Drone | AB1: EW/Utility | AC1: Alpha Strike | AD1: Static Defense | AE1: Flagship | AF1: Mobile Capital | AG1: Ultimate Siege | AH1: Conquest | AI1: Cultivator
A2: Line Infantry | B2: 1 | C2: 1.3 | D2: 1 | E2: 1 | F2: 1 | G2: 1 | H2: 1 | I2: 1 | J2: 1 | K2: 1 | L2: 1 | M2: 1 | N2: 1 | O2: 1 | P2: 1 | Q2: 1 | R2: 1 | S2: 1 | T2: 1 | U2: 1 | V2: 1 | W2: 1 | X2: 1 | Y2: 1 | Z2: 1 | AA2: 1 | AB2: 1 | AC2: 1 | AD2: 1 | AE2: 1 | AF2: 1 | AG2: 1 | AH2: 1 | AI2: 1
A3: Anti-Cavalry | B3: 1 | C3: 1 | D3: 1 | E3: 1 | F3: 1 | G3: 1.8 | H3: 1 | I3: 1 | J3: 1 | K3: 1 | L3: 1 | M3: 1 | N3: 1 | O3: 1 | P3: 1 | Q3: 1 | R3: 1 | S3: 1 | T3: 1 | U3: 1 | V3: 1 | W3: 1 | X3: 1 | Y3: 1 | Z3: 1 | AA3: 1 | AB3: 1 | AC3: 1 | AD3: 1 | AE3: 1 | AF3: 1 | AG3: 1 | AH3: 1 | AI3: 1
A4: Shock Infantry | B4: 1 | C4: 1 | D4: 1 | E4: 1.5 | F4: 1 | G4: 1 | H4: 1 | I4: 1 | J4: 1 | K4: 1 | L4: 1 | M4: 1 | N4: 1 | O4: 1 | P4: 1 | Q4: 1 | R4: 1 | S4: 1 | T4: 1 | U4: 1 | V4: 1 | W4: 1 | X4: 1 | Y4: 1 | Z4: 1 | AA4: 1 | AB4: 1 | AC4: 1 | AD4: 1 | AE4: 1 | AF4: 1 | AG4: 1 | AH4: 1 | AI4: 1
A5: Ranged | B5: 1.4 | C5: 1 | D5: 1 | E5: 1 | F5: 1 | G5: 1 | H5: 1 | I5: 1 | J5: 1 | K5: 1 | L5: 1 | M5: 1 | N5: 1 | O5: 1 | P5: 1 | Q5: 1 | R5: 1 | S5: 1 | T5: 1 | U5: 1 | V5: 1 | W5: 1 | X5: 1 | Y5: 1 | Z5: 1 | AA5: 1 | AB5: 1 | AC5: 1 | AD5: 1 | AE5: 1 | AF5: 1 | AG5: 1 | AH5: 1 | AI5: 1
A6: Skirmisher | B6: 1 | C6: 1 | D6: 1 | E6: 1 | F6: 1 | G6: 1 | H6: 1 | I6: 1 | J6: 1.8 | K6: 1 | L6: 1 | M6: 1.9 | N6: 1 | O6: 1 | P6: 1 | Q6: 1 | R6: 1 | S6: 1 | T6: 1 | U6: 1 | V6: 1 | W6: 1 | X6: 1 | Y6: 1 | Z6: 1 | AA6: 1 | AB6: 1 | AC6: 1 | AD6: 1 | AE6: 1 | AF6: 1 | AG6: 1 | AH6: 1 | AI6: 1
A7: Shock Cavalry | B7: 1 | C7: 1 | D7: 1 | E7: 1.7 | F7: 1 | G7: 1 | H7: 1 | I7: 1 | J7: 1.8 | K7: 1 | L7: 1 | M7: 1 | N7: 1 | O7: 1 | P7: 1 | Q7: 1 | R7: 1 | S7: 1 | T7: 1 | U7: 1 | V7: 1 | W7: 1 | X7: 1 | Y7: 1 | Z7: 1 | AA7: 1 | AB7: 1 | AC7: 1 | AD7: 1 | AE7: 1 | AF7: 1 | AG7: 1 | AH7: 1 | AI7: 1
A8: Elite Shock | B8: 1.5 | C8: 1 | D8: 1 | E8: 1 | F8: 1 | G8: 1 | H8: 1 | I8: 1 | J8: 1 | K8: 1 | L8: 1 | M8: 1 | N8: 1 | O8: 1 | P8: 1 | Q8: 1 | R8: 1 | S8: 1 | T8: 1 | U8: 1 | V8: 1 | W8: 1 | X8: 1 | Y8: 1 | Z8: 1 | AA8: 1 | AB8: 1 | AC8: 1 | AD8: 1 | AE8: 1 | AF8: 1 | AG8: 1 | AH8: 1 | AI8: 1
A9: Screen | B9: 1 | C9: 1 | D9: 1 | E9: 1 | F9: 1.4 | G9: 1 | H9: 1 | I9: 1 | J9: 1 | K9: 1 | L9: 1 | M9: 1 | N9: 1 | O9: 1 | P9: 1 | Q9: 1 | R9: 1 | S9: 1 | T9: 1 | U9: 1 | V9: 1 | W9: 1 | X9: 1 | Y9: 1 | Z9: 1 | AA9: 1 | AB9: 1 | AC9: 1.5 | AD9: 1 | AE9: 1 | AF9: 1 | AG9: 1 | AH9: 1 | AI9: 1
A10: Siege | B10: 1 | C10: 1 | D10: 1 | E10: 1 | F10: 1 | G10: 1 | H10: 1 | I10: 1 | J10: 1 | K10: 1 | L10: 1 | M10: 1 | N10: 1 | O10: 1 | P10: 1 | Q10: 1 | R10: 1 | S10: 1 | T10: 1 | U10: 1 | V10: 1 | W10: 1 | X10: 1 | Y10: 1 | Z10: 1 | AA10: 1 | AB10: 1 | AC10: 1 | AD10: 1.8 | AE10: 1 | AF10: 1 | AG10: 1 | AH10: 1 | AI10: 1
A11: Recon | B11: 0.4 | C11: 0.4 | D11: 0.4 | E11: 0.4 | F11: 0.4 | G11: 0.4 | H11: 0.4 | I11: 0.4 | J11: 0.4 | K11: 1 | L11: 0.4 | M11: 1 | N11: 0.4 | O11: 0.4 | P11: 0.4 | Q11: 0.4 | R11: 0.4 | S11: 0.4 | T11: 0.4 | U11: 0.4 | V11: 0.4 | W11: 0.4 | X11: 0.4 | Y11: 0.4 | Z11: 0.4 | AA11: 0.4 | AB11: 0.4 | AC11: 0.4 | AD11: 0.4 | AE11: 0.4 | AF11: 0.4 | AG11: 0.4 | AH11: 0.4 | AI11: 0.4
A12: Agent | B12: 1 | C12: 1 | D12: 1 | E12: 1 | F12: 1 | G12: 1 | H12: 1 | I12: 1 | J12: 1 | K12: 1 | L12: 1 | M12: 1 | N12: 1 | O12: 1 | P12: 1 | Q12: 1 | R12: 1 | S12: 1 | T12: 1 | U12: 1 | V12: 1 | W12: 1 | X12: 1 | Y12: 1 | Z12: 1 | AA12: 1 | AB12: 1 | AC12: 1 | AD12: 1 | AE12: 1 | AF12: 1 | AG12: 1 | AH12: 1.6 | AI12: 1
A13: Logistics | B13: 0.4 | C13: 0.4 | D13: 0.4 | E13: 0.4 | F13: 0.4 | G13: 0.4 | H13: 0.4 | I13: 0.4 | J13: 0.4 | K13: 1 | L13: 0.4 | M13: 1 | N13: 0.4 | O13: 0.4 | P13: 0.4 | Q13: 0.4 | R13: 0.4 | S13: 0.4 | T13: 0.4 | U13: 0.4 | V13: 0.4 | W13: 0.4 | X13: 0.4 | Y13: 0.4 | Z13: 0.4 | AA13: 0.4 | AB13: 0.4 | AC13: 0.4 | AD13: 0.4 | AE13: 0.4 | AF13: 0.4 | AG13: 0.4 | AH13: 0.4 | AI13: 0.4
... A35: Cultivator | B35: 1.3 | C35: 1 | D35: 1 | E35: 1 | F35: 1 | G35: 1 | H35: 1 | I35: 1 | J35: 1 | K35: 1 | L35: 1 | M35: 1 | N35: 1 | O35: 1 | P35: 1 | Q35: 1 | R35: 1 | S35: 1 | T35: 1 | U35: 1 | V35: 1 | W35: 1 | X35: 1 | Y35: 1 | Z35: 1 | AA35: 1 | AB35: 1 | AC35: 1 | AD35: 1 | AE35: 1 | AF35: 1 | AG35: 1 | AH35: 1 | AI35: 1
A37: Damage multiplier applied to attacker vs. that defender role. 1.0 = neutral. Design inputs (blue), server-tunable.

Sheet Research_Disciplines
A1: Discipline | B1: Era | C1: Branch | D1: Levels | E1: Grades | F1: Per-level effect (base) | G1: Grade breakthrough effect | H1: Prerequisite
A2: Agrarian Arts | B2: 1 | C2: Economy | D2: 0–1337 | E2: 42 | F2: +0.3% output in era systems / level | G2: Each grade (every 32 levels): unlocks a fork choice, a unit-grade gate, or an edict; requires Grade-Up cost + prerequisite (Grades_Realms) | H2: None
A3: Tribal Warfare | B3: 1 | C3: Military | D3: 0–1337 | E3: 42 | F3: +0.25% era unit effectiveness / level | G3: Each grade (every 32 levels): unlocks a fork choice, a unit-grade gate, or an edict; requires Grade-Up cost + prerequisite (Grades_Realms) | H3: None
A4: Hearth Law | B4: 1 | C4: Statecraft | D4: 0–1337 | E4: 42 | F4: +0.3% era governance metric / level | G4: Each grade (every 32 levels): unlocks a fork choice, a unit-grade gate, or an edict; requires Grade-Up cost + prerequisite (Grades_Realms) | H4: None
A5: Guild Economics | B5: 2 | C5: Economy | D5: 0–1337 | E5: 42 | F5: +0.3% output in era systems / level | G5: Each grade (every 32 levels): unlocks a fork choice, a unit-grade gate, or an edict; requires Grade-Up cost + prerequisite (Grades_Realms) | H5: All Era 1 disciplines at Grade 12+ and era ascension complete
A6: Feudal Arms | B6: 2 | C6: Military | D6: 0–1337 | E6: 42 | F6: +0.25% era unit effectiveness / level | G6: Each grade (every 32 levels): unlocks a fork choice, a unit-grade gate, or an edict; requires Grade-Up cost + prerequisite (Grades_Realms) | H6: All Era 1 disciplines at Grade 12+ and era ascension complete
A7: Crown & Charter | B7: 2 | C7: Statecraft | D7: 0–1337 | E7: 42 | F7: +0.3% era governance metric / level | G7: Each grade (every 32 levels): unlocks a fork choice, a unit-grade gate, or an edict; requires Grade-Up cost + prerequisite (Grades_Realms) | H7: All Era 1 disciplines at Grade 12+ and era ascension complete
A8: Mercantile Science | B8: 3 | C8: Economy | D8: 0–1337 | E8: 42 | F8: +0.3% output in era systems / level | G8: Each grade (every 32 levels): unlocks a fork choice, a unit-grade gate, or an edict; requires Grade-Up cost + prerequisite (Grades_Realms) | H8: All Era 2 disciplines at Grade 12+ and era ascension complete
A9: Powder Doctrine | B9: 3 | C9: Military | D9: 0–1337 | E9: 42 | F9: +0.25% era unit effectiveness / level | G9: Each grade (every 32 levels): unlocks a fork choice, a unit-grade gate, or an edict; requires Grade-Up cost + prerequisite (Grades_Realms) | H9: All Era 2 disciplines at Grade 12+ and era ascension complete
A10: Imperial Administration | B10: 3 | C10: Statecraft | D10: 0–1337 | E10: 42 | F10: +0.3% era governance metric / level | G10: Each grade (every 32 levels): unlocks a fork choice, a unit-grade gate, or an edict; requires Grade-Up cost + prerequisite (Grades_Realms) | H10: All Era 2 disciplines at Grade 12+ and era ascension complete
A11: Industrial Method | B11: 4 | C11: Economy | D11: 0–1337 | E11: 42 | F11: +0.3% output in era systems / level | G11: Each grade (every 32 levels): unlocks a fork choice, a unit-grade gate, or an edict; requires Grade-Up cost + prerequisite (Grades_Realms) | H11: All Era 3 disciplines at Grade 12+ and era ascension complete
A12: Combined Arms | B12: 4 | C12: Military | D12: 0–1337 | E12: 42 | F12: +0.25% era unit effectiveness / level | G12: Each grade (every 32 levels): unlocks a fork choice, a unit-grade gate, or an edict; requires Grade-Up cost + prerequisite (Grades_Realms) | H12: All Era 3 disciplines at Grade 12+ and era ascension complete
A13: Mass Society | B13: 4 | C13: Statecraft | D13: 0–1337 | E13: 42 | F13: +0.3% era governance metric / level | G13: Each grade (every 32 levels): unlocks a fork choice, a unit-grade gate, or an edict; requires Grade-Up cost + prerequisite (Grades_Realms) | H13: All Era 3 disciplines at Grade 12+ and era ascension complete
... A22: Dao of Rule | B22: 7 | C22: Statecraft | D22: 0–1337 | E22: 42 | F22: +0.3% era governance metric / level | G22: Each grade (every 32 levels): unlocks a fork choice, a unit-grade gate, or an edict; requires Grade-Up cost + prerequisite (Grades_Realms) | H22: All Era 6 disciplines at Grade 12+ and era ascension complete
A24: Research time uses the same 500-year curve as buildings: Time(L) = K × (L+1)^1.9 × 1.003^L with K from Building_Levels!H2, so a full 0→1337 discipline climb totals exactly 500 years. Research cost at level L = base_rp × (L+1)^2.2 × 1.0035^L; grade breakthroughs use Grades_Realms Qi/resource costs. Per-level effects soft-cap: total joint non-doctrine bonus ≤ +40% (GDD §17.1).

Sheet Equipment_Catalog
A1: Item | B1: Slot | C1: Tier | D1: Quality | E1: Bonus % | F1: Material Cost Mult | G1: Source | I1: Slot base %
A2: Crude Bronze War Axe | B2: Weapon | C2: 1 | D2: Crude | E2: =ROUND($J$2*(1+0.12*(C2-1))*0.7,1) -> 4.2 | F2: 0.8 | G2: Crafted (Smithy line by tier; Masterwork needs max Construction or Great Engineer) | I2: Weapon | J2: 6
A3: Standard Bronze War Axe | B3: Weapon | C3: 1 | D3: Standard | E3: =ROUND($J$2*(1+0.12*(C3-1))*1,1) -> 6 | F3: 1 | G3: Crafted (Smithy line by tier; Masterwork needs max Construction or Great Engineer) | I3: Protection | J3: 5
A4: Fine Bronze War Axe | B4: Weapon | C4: 1 | D4: Fine | E4: =ROUND($J$2*(1+0.12*(C4-1))*1.25,1) -> 7.5 | F4: 1.5 | G4: Crafted (Smithy line by tier; Masterwork needs max Construction or Great Engineer) | I4: Utility | J4: 4
A5: Masterwork Bronze War Axe | B5: Weapon | C5: 1 | D5: Masterwork | E5: =ROUND($J$2*(1+0.12*(C5-1))*1.6,1) -> 9.6 | F5: 2.6 | G5: Crafted (Smithy line by tier; Masterwork needs max Construction or Great Engineer)
A6: Relic Bronze War Axe | B6: Weapon | C6: 1 | D6: Relic | E6: =ROUND($J$2*(1+0.12*(C6-1))*2.2,1) -> 13.2 | F6: — | G6: Drop only: vaults, archaeology, tribulation forging | I6: Tier mult = 1 + 0.12×(tier−1)
A7: Crude Iron Pike | B7: Weapon | C7: 2 | D7: Crude | E7: =ROUND($J$2*(1+0.12*(C7-1))*0.7,1) -> 4.7 | F7: 0.8 | G7: Crafted (Smithy line by tier; Masterwork needs max Construction or Great Engineer)
A8: Standard Iron Pike | B8: Weapon | C8: 2 | D8: Standard | E8: =ROUND($J$2*(1+0.12*(C8-1))*1,1) -> 6.7 | F8: 1 | G8: Crafted (Smithy line by tier; Masterwork needs max Construction or Great Engineer)
A9: Fine Iron Pike | B9: Weapon | C9: 2 | D9: Fine | E9: =ROUND($J$2*(1+0.12*(C9-1))*1.25,1) -> 8.4 | F9: 1.5 | G9: Crafted (Smithy line by tier; Masterwork needs max Construction or Great Engineer)
A10: Masterwork Iron Pike | B10: Weapon | C10: 2 | D10: Masterwork | E10: =ROUND($J$2*(1+0.12*(C10-1))*1.6,1) -> 10.8 | F10: 2.6 | G10: Crafted (Smithy line by tier; Masterwork needs max Construction or Great Engineer)
A11: Relic Iron Pike | B11: Weapon | C11: 2 | D11: Relic | E11: =ROUND($J$2*(1+0.12*(C11-1))*2.2,1) -> 14.8 | F11: — | G11: Drop only: vaults, archaeology, tribulation forging
A12: Crude Folded Steel Blade | B12: Weapon | C12: 3 | D12: Crude | E12: =ROUND($J$2*(1+0.12*(C12-1))*0.7,1) -> 5.2 | F12: 0.8 | G12: Crafted (Smithy line by tier; Masterwork needs max Construction or Great Engineer)
A13: Standard Folded Steel Blade | B13: Weapon | C13: 3 | D13: Standard | E13: =ROUND($J$2*(1+0.12*(C13-1))*1,1) -> 7.4 | F13: 1 | G13: Crafted (Smithy line by tier; Masterwork needs max Construction or Great Engineer)
A14: Fine Folded Steel Blade | B14: Weapon | C14: 3 | D14: Fine | E14: =ROUND($J$2*(1+0.12*(C14-1))*1.25,1) -> 9.3 | F14: 1.5 | G14: Crafted (Smithy line by tier; Masterwork needs max Construction or Great Engineer)
A15: Masterwork Folded Steel Blade | B15: Weapon | C15: 3 | D15: Masterwork | E15: =ROUND($J$2*(1+0.12*(C15-1))*1.6,1) -> 11.9 | F15: 2.6 | G15: Crafted (Smithy line by tier; Masterwork needs max Construction or Great Engineer)
A16: Relic Folded Steel Blade | B16: Weapon | C16: 3 | D16: Relic | E16: =ROUND($J$2*(1+0.12*(C16-1))*2.2,1) -> 16.4 | F16: — | G16: Drop only: vaults, archaeology, tribulation forging
A17: Crude Rifled Musket | B17: Weapon | C17: 4 | D17: Crude | E17: =ROUND($J$2*(1+0.12*(C17-1))*0.7,1) -> 5.7 | F17: 0.8 | G17: Crafted (Smithy line by tier; Masterwork needs max Construction or Great Engineer)
A18: Standard Rifled Musket | B18: Weapon | C18: 4 | D18: Standard | E18: =ROUND($J$2*(1+0.12*(C18-1))*1,1) -> 8.2 | F18: 1 | G18: Crafted (Smithy line by tier; Masterwork needs max Construction or Great Engineer)
A19: Fine Rifled Musket | B19: Weapon | C19: 4 | D19: Fine | E19: =ROUND($J$2*(1+0.12*(C19-1))*1.25,1) -> 10.2 | F19: 1.5 | G19: Crafted (Smithy line by tier; Masterwork needs max Construction or Great Engineer)
A20: Masterwork Rifled Musket | B20: Weapon | C20: 4 | D20: Masterwork | E20: =ROUND($J$2*(1+0.12*(C20-1))*1.6,1) -> 13.1 | F20: 2.6 | G20: Crafted (Smithy line by tier; Masterwork needs max Construction or Great Engineer)
A21: Relic Rifled Musket | B21: Weapon | C21: 4 | D21: Relic | E21: =ROUND($J$2*(1+0.12*(C21-1))*2.2,1) -> 18 | F21: — | G21: Drop only: vaults, archaeology, tribulation forging
A22: Crude Bolt-Action Rifle | B22: Weapon | C22: 5 | D22: Crude | E22: =ROUND($J$2*(1+0.12*(C22-1))*0.7,1) -> 6.2 | F22: 0.8 | G22: Crafted (Smithy line by tier; Masterwork needs max Construction or Great Engineer)
A23: Standard Bolt-Action Rifle | B23: Weapon | C23: 5 | D23: Standard | E23: =ROUND($J$2*(1+0.12*(C23-1))*1,1) -> 8.9 | F23: 1 | G23: Crafted (Smithy line by tier; Masterwork needs max Construction or Great Engineer)
A24: Fine Bolt-Action Rifle | B24: Weapon | C24: 5 | D24: Fine | E24: =ROUND($J$2*(1+0.12*(C24-1))*1.25,1) -> 11.1 | F24: 1.5 | G24: Crafted (Smithy line by tier; Masterwork needs max Construction or Great Engineer)
A25: Masterwork Bolt-Action Rifle | B25: Weapon | C25: 5 | D25: Masterwork | E25: =ROUND($J$2*(1+0.12*(C25-1))*1.6,1) -> 14.2 | F25: 2.6 | G25: Crafted (Smithy line by tier; Masterwork needs max Construction or Great Engineer)
A26: Relic Bolt-Action Rifle | B26: Weapon | C26: 5 | D26: Relic | E26: =ROUND($J$2*(1+0.12*(C26-1))*2.2,1) -> 19.5 | F26: — | G26: Drop only: vaults, archaeology, tribulation forging
A27: Crude Composite Railgun | B27: Weapon | C27: 6 | D27: Crude | E27: =ROUND($J$2*(1+0.12*(C27-1))*0.7,1) -> 6.7 | F27: 0.8 | G27: Crafted (Smithy line by tier; Masterwork needs max Construction or Great Engineer)
A28: Standard Composite Railgun | B28: Weapon | C28: 6 | D28: Standard | E28: =ROUND($J$2*(1+0.12*(C28-1))*1,1) -> 9.6 | F28: 1 | G28: Crafted (Smithy line by tier; Masterwork needs max Construction or Great Engineer)
A29: Fine Composite Railgun | B29: Weapon | C29: 6 | D29: Fine | E29: =ROUND($J$2*(1+0.12*(C29-1))*1.25,1) -> 12 | F29: 1.5 | G29: Crafted (Smithy line by tier; Masterwork needs max Construction or Great Engineer)
A30: Masterwork Composite Railgun | B30: Weapon | C30: 6 | D30: Masterwork | E30: =ROUND($J$2*(1+0.12*(C30-1))*1.6,1) -> 15.4 | F30: 2.6 | G30: Crafted (Smithy line by tier; Masterwork needs max Construction or Great Engineer)
A31: Relic Composite Railgun | B31: Weapon | C31: 6 | D31: Relic | E31: =ROUND($J$2*(1+0.12*(C31-1))*2.2,1) -> 21.1 | F31: — | G31: Drop only: vaults, archaeology, tribulation forging
A32: Crude Titanium Gauss Cannon | B32: Weapon | C32: 7 | D32: Crude | E32: =ROUND($J$2*(1+0.12*(C32-1))*0.7,1) -> 7.2 | F32: 0.8 | G32: Crafted (Smithy line by tier; Masterwork needs max Construction or Great Engineer)
A33: Standard Titanium Gauss Cannon | B33: Weapon | C33: 7 | D33: Standard | E33: =ROUND($J$2*(1+0.12*(C33-1))*1,1) -> 10.3 | F33: 1 | G33: Crafted (Smithy line by tier; Masterwork needs max Construction or Great Engineer)
A34: Fine Titanium Gauss Cannon | B34: Weapon | C34: 7 | D34: Fine | E34: =ROUND($J$2*(1+0.12*(C34-1))*1.25,1) -> 12.9 | F34: 1.5 | G34: Crafted (Smithy line by tier; Masterwork needs max Construction or Great Engineer)
A35: Masterwork Titanium Gauss Cannon | B35: Weapon | C35: 7 | D35: Masterwork | E35: =ROUND($J$2*(1+0.12*(C35-1))*1.6,1) -> 16.5 | F35: 2.6 | G35: Crafted (Smithy line by tier; Masterwork needs max Construction or Great Engineer)
A36: Relic Titanium Gauss Cannon | B36: Weapon | C36: 7 | D36: Relic | E36: =ROUND($J$2*(1+0.12*(C36-1))*2.2,1) -> 22.7 | F36: — | G36: Drop only: vaults, archaeology, tribulation forging
A37: Crude Exotic Plasma Lance | B37: Weapon | C37: 8 | D37: Crude | E37: =ROUND($J$2*(1+0.12*(C37-1))*0.7,1) -> 7.7 | F37: 0.8 | G37: Crafted (Smithy line by tier; Masterwork needs max Construction or Great Engineer)
A38: Standard Exotic Plasma Lance | B38: Weapon | C38: 8 | D38: Standard | E38: =ROUND($J$2*(1+0.12*(C38-1))*1,1) -> 11 | F38: 1 | G38: Crafted (Smithy line by tier; Masterwork needs max Construction or Great Engineer)
